2023-12-29 20:21:02,968 INFO    MainThread:101557 [wandb_setup.py:_flush():76] Current SDK version is 0.16.1
2023-12-29 20:21:02,968 INFO    MainThread:101557 [wandb_setup.py:_flush():76] Configure stats pid to 101557
2023-12-29 20:21:02,968 INFO    MainThread:101557 [wandb_setup.py:_flush():76] Loading settings from /home/wangzili/.config/wandb/settings
2023-12-29 20:21:02,968 INFO    MainThread:101557 [wandb_setup.py:_flush():76] Loading settings from /cpfs01/projects-HDD/cfff-23ba4487e9df_HDD/wangzili/LLaMA-Factory/wandb/settings
2023-12-29 20:21:02,968 INFO    MainThread:101557 [wandb_setup.py:_flush():76] Loading settings from environment variables: {}
2023-12-29 20:21:02,968 INFO    MainThread:101557 [wandb_setup.py:_flush():76] Applying setup settings: {'_disable_service': False}
2023-12-29 20:21:02,968 INFO    MainThread:101557 [wandb_setup.py:_flush():76] Inferring run settings from compute environment: {'program_relpath': 'src/train_bash.py', 'program_abspath': '/cpfs01/projects-HDD/cfff-23ba4487e9df_HDD/wangzili/LLaMA-Factory/src/train_bash.py', 'program': '/cpfs01/projects-HDD/cfff-23ba4487e9df_HDD/wangzili/LLaMA-Factory/src/train_bash.py'}
2023-12-29 20:21:02,968 INFO    MainThread:101557 [wandb_init.py:_log_setup():524] Logging user logs to /cpfs01/projects-HDD/cfff-23ba4487e9df_HDD/wangzili/LLaMA-Factory/wandb/run-20231229_202102-3oommjvv/logs/debug.log
2023-12-29 20:21:02,968 INFO    MainThread:101557 [wandb_init.py:_log_setup():525] Logging internal logs to /cpfs01/projects-HDD/cfff-23ba4487e9df_HDD/wangzili/LLaMA-Factory/wandb/run-20231229_202102-3oommjvv/logs/debug-internal.log
2023-12-29 20:21:02,968 INFO    MainThread:101557 [wandb_init.py:init():564] calling init triggers
2023-12-29 20:21:02,968 INFO    MainThread:101557 [wandb_init.py:init():571] wandb.init called with sweep_config: {}
config: {}
2023-12-29 20:21:02,968 INFO    MainThread:101557 [wandb_init.py:init():614] starting backend
2023-12-29 20:21:02,968 INFO    MainThread:101557 [wandb_init.py:init():618] setting up manager
2023-12-29 20:21:02,969 INFO    MainThread:101557 [backend.py:_multiprocessing_setup():105] multiprocessing start_methods=fork,spawn,forkserver, using: spawn
2023-12-29 20:21:02,970 INFO    MainThread:101557 [wandb_init.py:init():624] backend started and connected
2023-12-29 20:21:02,973 INFO    MainThread:101557 [wandb_init.py:init():716] updated telemetry
2023-12-29 20:21:02,978 INFO    MainThread:101557 [wandb_init.py:init():749] communicating run to backend with 90.0 second timeout
2023-12-29 20:22:05,398 INFO    Thread-4 (wrapped_target):101557 [retry.py:__call__():172] Retry attempt failed:
Traceback (most recent call last):
  File "/cpfs01/projects-HDD/cfff-23ba4487e9df_HDD/wangzili/miniconda3/envs/torch2/lib/python3.10/site-packages/urllib3/connection.py", line 174, in _new_conn
    conn = connection.create_connection(
  File "/cpfs01/projects-HDD/cfff-23ba4487e9df_HDD/wangzili/miniconda3/envs/torch2/lib/python3.10/site-packages/urllib3/util/connection.py", line 95, in create_connection
    raise err
  File "/cpfs01/projects-HDD/cfff-23ba4487e9df_HDD/wangzili/miniconda3/envs/torch2/lib/python3.10/site-packages/urllib3/util/connection.py", line 85, in create_connection
    sock.connect(sa)
TimeoutError: timed out

During handling of the above exception, another exception occurred:

Traceback (most recent call last):
  File "/cpfs01/projects-HDD/cfff-23ba4487e9df_HDD/wangzili/miniconda3/envs/torch2/lib/python3.10/site-packages/urllib3/connectionpool.py", line 715, in urlopen
    httplib_response = self._make_request(
  File "/cpfs01/projects-HDD/cfff-23ba4487e9df_HDD/wangzili/miniconda3/envs/torch2/lib/python3.10/site-packages/urllib3/connectionpool.py", line 404, in _make_request
    self._validate_conn(conn)
  File "/cpfs01/projects-HDD/cfff-23ba4487e9df_HDD/wangzili/miniconda3/envs/torch2/lib/python3.10/site-packages/urllib3/connectionpool.py", line 1058, in _validate_conn
    conn.connect()
  File "/cpfs01/projects-HDD/cfff-23ba4487e9df_HDD/wangzili/miniconda3/envs/torch2/lib/python3.10/site-packages/urllib3/connection.py", line 363, in connect
    self.sock = conn = self._new_conn()
  File "/cpfs01/projects-HDD/cfff-23ba4487e9df_HDD/wangzili/miniconda3/envs/torch2/lib/python3.10/site-packages/urllib3/connection.py", line 179, in _new_conn
    raise ConnectTimeoutError(
urllib3.exceptions.ConnectTimeoutError: (<urllib3.connection.HTTPSConnection object at 0x7f9c70233b50>, 'Connection to api.wandb.ai timed out. (connect timeout=20)')

During handling of the above exception, another exception occurred:

Traceback (most recent call last):
  File "/cpfs01/projects-HDD/cfff-23ba4487e9df_HDD/wangzili/miniconda3/envs/torch2/lib/python3.10/site-packages/requests/adapters.py", line 486, in send
    resp = conn.urlopen(
  File "/cpfs01/projects-HDD/cfff-23ba4487e9df_HDD/wangzili/miniconda3/envs/torch2/lib/python3.10/site-packages/urllib3/connectionpool.py", line 799, in urlopen
    retries = retries.increment(
  File "/cpfs01/projects-HDD/cfff-23ba4487e9df_HDD/wangzili/miniconda3/envs/torch2/lib/python3.10/site-packages/urllib3/util/retry.py", line 592, in increment
    raise MaxRetryError(_pool, url, error or ResponseError(cause))
urllib3.exceptions.MaxRetryError: HTTPSConnectionPool(host='api.wandb.ai', port=443): Max retries exceeded with url: /graphql (Caused by ConnectTimeoutError(<urllib3.connection.HTTPSConnection object at 0x7f9c70233b50>, 'Connection to api.wandb.ai timed out. (connect timeout=20)'))

During handling of the above exception, another exception occurred:

Traceback (most recent call last):
  File "/cpfs01/projects-HDD/cfff-23ba4487e9df_HDD/wangzili/miniconda3/envs/torch2/lib/python3.10/site-packages/wandb/sdk/lib/retry.py", line 131, in __call__
    result = self._call_fn(*args, **kwargs)
  File "/cpfs01/projects-HDD/cfff-23ba4487e9df_HDD/wangzili/miniconda3/envs/torch2/lib/python3.10/site-packages/wandb/sdk/internal/internal_api.py", line 369, in execute
    return self.client.execute(*args, **kwargs)  # type: ignore
  File "/cpfs01/projects-HDD/cfff-23ba4487e9df_HDD/wangzili/miniconda3/envs/torch2/lib/python3.10/site-packages/wandb/vendor/gql-0.2.0/wandb_gql/client.py", line 52, in execute
    result = self._get_result(document, *args, **kwargs)
  File "/cpfs01/projects-HDD/cfff-23ba4487e9df_HDD/wangzili/miniconda3/envs/torch2/lib/python3.10/site-packages/wandb/vendor/gql-0.2.0/wandb_gql/client.py", line 60, in _get_result
    return self.transport.execute(document, *args, **kwargs)
  File "/cpfs01/projects-HDD/cfff-23ba4487e9df_HDD/wangzili/miniconda3/envs/torch2/lib/python3.10/site-packages/wandb/sdk/lib/gql_request.py", line 58, in execute
    request = self.session.post(self.url, **post_args)
  File "/cpfs01/projects-HDD/cfff-23ba4487e9df_HDD/wangzili/miniconda3/envs/torch2/lib/python3.10/site-packages/requests/sessions.py", line 637, in post
    return self.request("POST", url, data=data, json=json, **kwargs)
  File "/cpfs01/projects-HDD/cfff-23ba4487e9df_HDD/wangzili/miniconda3/envs/torch2/lib/python3.10/site-packages/requests/sessions.py", line 589, in request
    resp = self.send(prep, **send_kwargs)
  File "/cpfs01/projects-HDD/cfff-23ba4487e9df_HDD/wangzili/miniconda3/envs/torch2/lib/python3.10/site-packages/requests/sessions.py", line 703, in send
    r = adapter.send(request, **kwargs)
  File "/cpfs01/projects-HDD/cfff-23ba4487e9df_HDD/wangzili/miniconda3/envs/torch2/lib/python3.10/site-packages/requests/adapters.py", line 507, in send
    raise ConnectTimeout(e, request=request)
requests.exceptions.ConnectTimeout: HTTPSConnectionPool(host='api.wandb.ai', port=443): Max retries exceeded with url: /graphql (Caused by ConnectTimeoutError(<urllib3.connection.HTTPSConnection object at 0x7f9c70233b50>, 'Connection to api.wandb.ai timed out. (connect timeout=20)'))
2023-12-29 20:22:32,995 ERROR   MainThread:101557 [wandb_init.py:init():775] encountered error: Run initialization has timed out after 90.0 sec. 
Please refer to the documentation for additional information: https://docs.wandb.ai/guides/track/tracking-faq#initstarterror-error-communicating-with-wandb-process-
2023-12-29 20:22:35,003 ERROR   MainThread:101557 [wandb_init.py:init():1188] Run initialization has timed out after 90.0 sec. 
Please refer to the documentation for additional information: https://docs.wandb.ai/guides/track/tracking-faq#initstarterror-error-communicating-with-wandb-process-
Traceback (most recent call last):
  File "/cpfs01/projects-HDD/cfff-23ba4487e9df_HDD/wangzili/miniconda3/envs/torch2/lib/python3.10/site-packages/wandb/sdk/wandb_init.py", line 1170, in init
    run = wi.init()
  File "/cpfs01/projects-HDD/cfff-23ba4487e9df_HDD/wangzili/miniconda3/envs/torch2/lib/python3.10/site-packages/wandb/sdk/wandb_init.py", line 781, in init
    raise error
wandb.errors.CommError: Run initialization has timed out after 90.0 sec. 
Please refer to the documentation for additional information: https://docs.wandb.ai/guides/track/tracking-faq#initstarterror-error-communicating-with-wandb-process-
